Workbook
Name ttUseToday: Dashboard!$C$6
Name ttChosenDate: Dashboard!$C$7
Name ttValueDate: Dashboard!$C$8
Name ttFileDate: Dashboard!$C$9
Name ttOutputFolder: Dashboard!$C$20
Name ttStatus: Dashboard!$B$25
Name ttAmountUnit: Config!$C$5
Name ttFileNamePattern: Config!$C$6
Name ttFileDateOffset: Config!$C$7
Name ttEnforceBalance: Config!$C$8
Name ttTrailingNewline: Config!$C$9
Name ttInputFolder: Config!$C$10
Name ttInputPattern: Config!$C$11
Name ttImportSetsDate: Config!$C$12
Name ttLastImport: Import!$C$6

Sheet Dashboard
A1: TTUM GENERATOR
A2: Choose the date, get the day's amounts in, then click Generate.
B3: Buttons doing nothing? Close Excel, right-click this file in File Explorer, Properties, tick Unblock, reopen. Full list on the Setup sheet.
B5: STEP 1 Which day is this file for?
B6: Use today's date? | C6: Yes
B7: ...or generate for this date
B8: Value date used in the records | C8: =IF(ttUseToday="Yes",TODAY(),IF(ttChosenDate="","",ttChosenDate))
B9: File-name date (offset is set on Config) | C9: =ttValueDate+ttFileDateOffset
B10: Leave the first box on Yes for today's file. For any other day set it to No and type the date below it - or just click Generate for Another Date and type the date when asked. Importing a settlement file also sets the date from the file itself.
B12: STEP 2 Enter the amounts, or import them
B13: Rows included | C13: =COUNTIF(Entries!$A$5:$A$104,"Yes")
B14: Total debit | C14: =Entries!$L$1
B15: Total credit | C15: =Entries!$L$2
B16: Difference (must be 0.00) | C16: =Entries!$L$3
B17: Type the amounts on the Entries sheet, or click Import Latest Input File to read them out of the settlement file. The input folder is set on the Config sheet.
B19: STEP 3 Choose where the file goes, then generate
B20: Output folder
B21: Type or paste a full folder path here, for example D:\TTUM\Daily - or click Choose Output Folder. Left blank, files go to a TTUM_Output folder beside this workbook.
B22: File name | C22: =SUBSTITUTE(SUBSTITUTE(SUBSTITUTE(ttFileNamePattern,"{DDMMYYYY}",TEXT(ttFileDate,"ddmmyyyy")),"{DDMMYY}",TEXT(ttFileDate,"ddmmyy")),"{YYYY}",TEXT(ttFileDate,"yyyy"))
B24: Status
B25: Ready.
B27: Every button is also on the Alt+F8 macro list, and the Text Output sheet builds the same file with no macros at all.

Sheet Entries
A1: DAILY TTUM ENTRIES | K1: Total debit | L1: =SUMIFS($E$5:$E$104,$D$5:$D$104,"D",$A$5:$A$104,"Yes")/IF(ttAmountUnit="Paise",100,1)
A2: Type today's amount and Dr/Cr against each line. Blank rows are ignored. | K2: Total credit | L2: =SUMIFS($E$5:$E$104,$D$5:$D$104,"C",$A$5:$A$104,"Yes")/IF(ttAmountUnit="Paise",100,1)
A3: ="Total debit "&TEXT($L$1,"#,##0.00")&" Total credit "&TEXT($L$2,"#,##0.00")&" Difference "&TEXT($L$3,"#,##0.00")&IF($L$3=0," (balanced)"," <<< THESE MUST MATCH") | K3: Difference | L3: =$L$1-$L$2
A4: Include | B4: Description | C4: Account Number | D4: Dr/Cr | E4: Amount as keyed | F4: Narration template | G4: Reads as (INR) | H4: Import match text | I4: Seq
A5: Yes | B5: VI settlement | C5: 00993562511731 | D5: D | F5: PROPELG VI settlement {DDMMYY} | G5: =IF($E5="","",$E5/IF(ttAmountUnit="Paise",100,1)) | H5: VI settlement | I5: =IF(AND($A5="Yes",$E5<>""),SUMPRODUCT(($A$5:$A5="Yes")*($E$5:$E5<>"")),"")
A6: Yes | B6: MC settlement | C6: 00993562511732 | D6: D | F6: PROPELG MC settlement {DDMMYY} | G6: =IF($E6="","",$E6/IF(ttAmountUnit="Paise",100,1)) | H6: MC settlement | I6: =IF(AND($A6="Yes",$E6<>""),SUMPRODUCT(($A$5:$A6="Yes")*($E$5:$E6<>"")),"")
A7: Yes | B7: MC commission received | C7: 00993564610119 | D7: C | F7: PROPELG MC comm recd {DDMMYY} | G7: =IF($E7="","",$E7/IF(ttAmountUnit="Paise",100,1)) | H7: MC comm recd | I7: =IF(AND($A7="Yes",$E7<>""),SUMPRODUCT(($A$5:$A7="Yes")*($E$5:$E7<>"")),"")
A8: Yes | B8: VI commission received | C8: 00993564610122 | D8: C | F8: PROPELG VI comm recd {DDMMYY} | G8: =IF($E8="","",$E8/IF(ttAmountUnit="Paise",100,1)) | H8: VI comm recd | I8: =IF(AND($A8="Yes",$E8<>""),SUMPRODUCT(($A$5:$A8="Yes")*($E$5:$E8<>"")),"")
A9: Yes | B9: MC GST on commission | C9: 00993564610119 | D9: C | F9: PROPELG MC GST comm recd {DDMMYY} | G9: =IF($E9="","",$E9/IF(ttAmountUnit="Paise",100,1)) | H9: MC GST comm recd | I9: =IF(AND($A9="Yes",$E9<>""),SUMPRODUCT(($A$5:$A9="Yes")*($E$5:$E9<>"")),"")
A10: Yes | B10: VI GST on commission | C10: 00993564610122 | D10: C | F10: PROPELG VI GST comm recd {DDMMYY} | G10: =IF($E10="","",$E10/IF(ttAmountUnit="Paise",100,1)) | H10: VI GST comm recd | I10: =IF(AND($A10="Yes",$E10<>""),SUMPRODUCT(($A$5:$A10="Yes")*($E$5:$E10<>"")),"")
A11: Yes | B11: MC Non-GST commission | C11: 00993564610119 | D11: C | F11: PROPELG MC Non GST comm recd {DDMMYY} | G11: =IF($E11="","",$E11/IF(ttAmountUnit="Paise",100,1)) | H11: MC Non GST comm recd | I11: =IF(AND($A11="Yes",$E11<>""),SUMPRODUCT(($A$5:$A11="Yes")*($E$5:$E11<>"")),"")
A12: Yes | B12: VI Non-GST commission | C12: 00993564610122 | D12: C | F12: PROPELG VI Non GST comm recd {DDMMYY} | G12: =IF($E12="","",$E12/IF(ttAmountUnit="Paise",100,1)) | H12: VI Non GST comm recd | I12: =IF(AND($A12="Yes",$E12<>""),SUMPRODUCT(($A$5:$A12="Yes")*($E$5:$E12<>"")),"")
A13: Yes | B13: Net settlement to Prp India | C13: 200999103427 | D13: C | F13: PROPELG-TXN Prp India {DDMMYY} {DDMMYY} | G13: =IF($E13="","",$E13/IF(ttAmountUnit="Paise",100,1)) | H13: Nodal | I13: =IF(AND($A13="Yes",$E13<>""),SUMPRODUCT(($A$5:$A13="Yes")*($E$5:$E13<>"")),"")
G14: =IF($E14="","",$E14/IF(ttAmountUnit="Paise",100,1)) | I14: =IF(AND($A14="Yes",$E14<>""),SUMPRODUCT(($A$5:$A14="Yes")*($E$5:$E14<>"")),"")
G15: =IF($E15="","",$E15/IF(ttAmountUnit="Paise",100,1)) | I15: =IF(AND($A15="Yes",$E15<>""),SUMPRODUCT(($A$5:$A15="Yes")*($E$5:$E15<>"")),"")
G16: =IF($E16="","",$E16/IF(ttAmountUnit="Paise",100,1)) | I16: =IF(AND($A16="Yes",$E16<>""),SUMPRODUCT(($A$5:$A16="Yes")*($E$5:$E16<>"")),"")
G17: =IF($E17="","",$E17/IF(ttAmountUnit="Paise",100,1)) | I17: =IF(AND($A17="Yes",$E17<>""),SUMPRODUCT(($A$5:$A17="Yes")*($E$5:$E17<>"")),"")
G18: =IF($E18="","",$E18/IF(ttAmountUnit="Paise",100,1)) | I18: =IF(AND($A18="Yes",$E18<>""),SUMPRODUCT(($A$5:$A18="Yes")*($E$5:$E18<>"")),"")
G19: =IF($E19="","",$E19/IF(ttAmountUnit="Paise",100,1)) | I19: =IF(AND($A19="Yes",$E19<>""),SUMPRODUCT(($A$5:$A19="Yes")*($E$5:$E19<>"")),"")
G20: =IF($E20="","",$E20/IF(ttAmountUnit="Paise",100,1)) | I20: =IF(AND($A20="Yes",$E20<>""),SUMPRODUCT(($A$5:$A20="Yes")*($E$5:$E20<>"")),"")
G21: =IF($E21="","",$E21/IF(ttAmountUnit="Paise",100,1)) | I21: =IF(AND($A21="Yes",$E21<>""),SUMPRODUCT(($A$5:$A21="Yes")*($E$5:$E21<>"")),"")
G22: =IF($E22="","",$E22/IF(ttAmountUnit="Paise",100,1)) | I22: =IF(AND($A22="Yes",$E22<>""),SUMPRODUCT(($A$5:$A22="Yes")*($E$5:$E22<>"")),"")
G23: =IF($E23="","",$E23/IF(ttAmountUnit="Paise",100,1)) | I23: =IF(AND($A23="Yes",$E23<>""),SUMPRODUCT(($A$5:$A23="Yes")*($E$5:$E23<>"")),"")
G24: =IF($E24="","",$E24/IF(ttAmountUnit="Paise",100,1)) | I24: =IF(AND($A24="Yes",$E24<>""),SUMPRODUCT(($A$5:$A24="Yes")*($E$5:$E24<>"")),"")
G25: =IF($E25="","",$E25/IF(ttAmountUnit="Paise",100,1)) | I25: =IF(AND($A25="Yes",$E25<>""),SUMPRODUCT(($A$5:$A25="Yes")*($E$5:$E25<>"")),"")
... G104: =IF($E104="","",$E104/IF(ttAmountUnit="Paise",100,1)) | I104: =IF(AND($A104="Yes",$E104<>""),SUMPRODUCT(($A$5:$A104="Yes")*($E$5:$E104<>"")),"")
A106: Amount as keyed: with Config set to Paise (the default), type the figure exactly as the settlement report shows it - the last two digits are the paise, so 47400 is 474.00. The Reads as (INR) column shows how each figure will be understood. Narration tokens {DDMMYY} {DDMMYYYY} {DD} {MM} {YY} {YYYY} are replaced with the value date; the narration must fit 35 characters after substitution. Import match text is what an incoming settlement line's narration must contain for its amount to land on this row - only the amount and Dr/Cr are imported, never the account number or the narration.

Sheet Import
A1: IMPORT FROM SETTLEMENT FILE
A2: The day's figures, read out of the file the settlement system produces.
B3: With macros working: | C3: click Import Latest Input File on the Dashboard. The file's lines land here, you get a summary to check, and the amounts go onto Entries.
B4: With macros blocked: | C4: open the settlement file in Notepad, select all, copy, and paste into cell B10 below. Then copy the Amount to key column onto the Amount column of the Entries sheet, matching the rows named under Goes to.
B6: Last import | C6: Nothing imported yet.
B7: ="Lines below "&COUNTIF($B$10:$B$109,"?*")&" Debit "&TEXT(SUMIF($F$10:$F$109,"D",$E$10:$E$109)/100,"#,##0.00")&" Credit "&TEXT(SUMIF($F$10:$F$109,"C",$E$10:$E$109)/100,"#,##0.00")&" Difference "&TEXT((SUMIF($F$10:$F$109,"D",$E$10:$E$109)-SUMIF($F$10:$F$109,"C",$E$10:$E$109))/100,"#,##0.00")
A9: # | B9: Line from the settlement file | C9: Account | D9: Value date | E9: Amount (paise) | F9: Dr/Cr | G9: Narration | H9: Amount to key | I9: Goes to
A10: 1 | C10: =IF(LEN($B10)<14,"",TRIM(MID($B10,1,14))) | D10: =IF(LEN($B10)<22,"",DATE(VALUE(MID($B10,19,4)),VALUE(MID($B10,17,2)),VALUE(MID($B10,15,2)))) | E10: =IF(LEN($B10)<45,"",VALUE(MID($B10,23,23))) | F10: =IF(LEN($B10)<46,"",MID($B10,46,1)) | G10: =IF(LEN($B10)<116,"",TRIM(MID($B10,82,35))) | H10: =IF($E10="","",$E10/IF(ttAmountUnit="Paise",1,100)) | I10: =IF($G10="","",IF($J10=0,"-- no match --",INDEX(Entries!$B$5:$B$104,$J10))) | J10: =IF($G10="","",SUMPRODUCT(MAX((Entries!$H$5:$H$104<>"")*ISNUMBER(SEARCH(Entries!$H$5:$H$104,$G10&""))*(ROW(Entries!$H$5:$H$104)-4))))
A11: 2 | C11: =IF(LEN($B11)<14,"",TRIM(MID($B11,1,14))) | D11: =IF(LEN($B11)<22,"",DATE(VALUE(MID($B11,19,4)),VALUE(MID($B11,17,2)),VALUE(MID($B11,15,2)))) | E11: =IF(LEN($B11)<45,"",VALUE(MID($B11,23,23))) | F11: =IF(LEN($B11)<46,"",MID($B11,46,1)) | G11: =IF(LEN($B11)<116,"",TRIM(MID($B11,82,35))) | H11: =IF($E11="","",$E11/IF(ttAmountUnit="Paise",1,100)) | I11: =IF($G11="","",IF($J11=0,"-- no match --",INDEX(Entries!$B$5:$B$104,$J11))) | J11: =IF($G11="","",SUMPRODUCT(MAX((Entries!$H$5:$H$104<>"")*ISNUMBER(SEARCH(Entries!$H$5:$H$104,$G11&""))*(ROW(Entries!$H$5:$H$104)-4))))
A12: 3 | C12: =IF(LEN($B12)<14,"",TRIM(MID($B12,1,14))) | D12: =IF(LEN($B12)<22,"",DATE(VALUE(MID($B12,19,4)),VALUE(MID($B12,17,2)),VALUE(MID($B12,15,2)))) | E12: =IF(LEN($B12)<45,"",VALUE(MID($B12,23,23))) | F12: =IF(LEN($B12)<46,"",MID($B12,46,1)) | G12: =IF(LEN($B12)<116,"",TRIM(MID($B12,82,35))) | H12: =IF($E12="","",$E12/IF(ttAmountUnit="Paise",1,100)) | I12: =IF($G12="","",IF($J12=0,"-- no match --",INDEX(Entries!$B$5:$B$104,$J12))) | J12: =IF($G12="","",SUMPRODUCT(MAX((Entries!$H$5:$H$104<>"")*ISNUMBER(SEARCH(Entries!$H$5:$H$104,$G12&""))*(ROW(Entries!$H$5:$H$104)-4))))
A13: 4 | C13: =IF(LEN($B13)<14,"",TRIM(MID($B13,1,14))) | D13: =IF(LEN($B13)<22,"",DATE(VALUE(MID($B13,19,4)),VALUE(MID($B13,17,2)),VALUE(MID($B13,15,2)))) | E13: =IF(LEN($B13)<45,"",VALUE(MID($B13,23,23))) | F13: =IF(LEN($B13)<46,"",MID($B13,46,1)) | G13: =IF(LEN($B13)<116,"",TRIM(MID($B13,82,35))) | H13: =IF($E13="","",$E13/IF(ttAmountUnit="Paise",1,100)) | I13: =IF($G13="","",IF($J13=0,"-- no match --",INDEX(Entries!$B$5:$B$104,$J13))) | J13: =IF($G13="","",SUMPRODUCT(MAX((Entries!$H$5:$H$104<>"")*ISNUMBER(SEARCH(Entries!$H$5:$H$104,$G13&""))*(ROW(Entries!$H$5:$H$104)-4))))
A14: 5 | C14: =IF(LEN($B14)<14,"",TRIM(MID($B14,1,14))) | D14: =IF(LEN($B14)<22,"",DATE(VALUE(MID($B14,19,4)),VALUE(MID($B14,17,2)),VALUE(MID($B14,15,2)))) | E14: =IF(LEN($B14)<45,"",VALUE(MID($B14,23,23))) | F14: =IF(LEN($B14)<46,"",MID($B14,46,1)) | G14: =IF(LEN($B14)<116,"",TRIM(MID($B14,82,35))) | H14: =IF($E14="","",$E14/IF(ttAmountUnit="Paise",1,100)) | I14: =IF($G14="","",IF($J14=0,"-- no match --",INDEX(Entries!$B$5:$B$104,$J14))) | J14: =IF($G14="","",SUMPRODUCT(MAX((Entries!$H$5:$H$104<>"")*ISNUMBER(SEARCH(Entries!$H$5:$H$104,$G14&""))*(ROW(Entries!$H$5:$H$104)-4))))
A15: 6 | C15: =IF(LEN($B15)<14,"",TRIM(MID($B15,1,14))) | D15: =IF(LEN($B15)<22,"",DATE(VALUE(MID($B15,19,4)),VALUE(MID($B15,17,2)),VALUE(MID($B15,15,2)))) | E15: =IF(LEN($B15)<45,"",VALUE(MID($B15,23,23))) | F15: =IF(LEN($B15)<46,"",MID($B15,46,1)) | G15: =IF(LEN($B15)<116,"",TRIM(MID($B15,82,35))) | H15: =IF($E15="","",$E15/IF(ttAmountUnit="Paise",1,100)) | I15: =IF($G15="","",IF($J15=0,"-- no match --",INDEX(Entries!$B$5:$B$104,$J15))) | J15: =IF($G15="","",SUMPRODUCT(MAX((Entries!$H$5:$H$104<>"")*ISNUMBER(SEARCH(Entries!$H$5:$H$104,$G15&""))*(ROW(Entries!$H$5:$H$104)-4))))
A16: 7 | C16: =IF(LEN($B16)<14,"",TRIM(MID($B16,1,14))) | D16: =IF(LEN($B16)<22,"",DATE(VALUE(MID($B16,19,4)),VALUE(MID($B16,17,2)),VALUE(MID($B16,15,2)))) | E16: =IF(LEN($B16)<45,"",VALUE(MID($B16,23,23))) | F16: =IF(LEN($B16)<46,"",MID($B16,46,1)) | G16: =IF(LEN($B16)<116,"",TRIM(MID($B16,82,35))) | H16: =IF($E16="","",$E16/IF(ttAmountUnit="Paise",1,100)) | I16: =IF($G16="","",IF($J16=0,"-- no match --",INDEX(Entries!$B$5:$B$104,$J16))) | J16: =IF($G16="","",SUMPRODUCT(MAX((Entries!$H$5:$H$104<>"")*ISNUMBER(SEARCH(Entries!$H$5:$H$104,$G16&""))*(ROW(Entries!$H$5:$H$104)-4))))
A17: 8 | C17: =IF(LEN($B17)<14,"",TRIM(MID($B17,1,14))) | D17: =IF(LEN($B17)<22,"",DATE(VALUE(MID($B17,19,4)),VALUE(MID($B17,17,2)),VALUE(MID($B17,15,2)))) | E17: =IF(LEN($B17)<45,"",VALUE(MID($B17,23,23))) | F17: =IF(LEN($B17)<46,"",MID($B17,46,1)) | G17: =IF(LEN($B17)<116,"",TRIM(MID($B17,82,35))) | H17: =IF($E17="","",$E17/IF(ttAmountUnit="Paise",1,100)) | I17: =IF($G17="","",IF($J17=0,"-- no match --",INDEX(Entries!$B$5:$B$104,$J17))) | J17: =IF($G17="","",SUMPRODUCT(MAX((Entries!$H$5:$H$104<>"")*ISNUMBER(SEARCH(Entries!$H$5:$H$104,$G17&""))*(ROW(Entries!$H$5:$H$104)-4))))
A18: 9 | C18: =IF(LEN($B18)<14,"",TRIM(MID($B18,1,14))) | D18: =IF(LEN($B18)<22,"",DATE(VALUE(MID($B18,19,4)),VALUE(MID($B18,17,2)),VALUE(MID($B18,15,2)))) | E18: =IF(LEN($B18)<45,"",VALUE(MID($B18,23,23))) | F18: =IF(LEN($B18)<46,"",MID($B18,46,1)) | G18: =IF(LEN($B18)<116,"",TRIM(MID($B18,82,35))) | H18: =IF($E18="","",$E18/IF(ttAmountUnit="Paise",1,100)) | I18: =IF($G18="","",IF($J18=0,"-- no match --",INDEX(Entries!$B$5:$B$104,$J18))) | J18: =IF($G18="","",SUMPRODUCT(MAX((Entries!$H$5:$H$104<>"")*ISNUMBER(SEARCH(Entries!$H$5:$H$104,$G18&""))*(ROW(Entries!$H$5:$H$104)-4))))
A19: 10 | C19: =IF(LEN($B19)<14,"",TRIM(MID($B19,1,14))) | D19: =IF(LEN($B19)<22,"",DATE(VALUE(MID($B19,19,4)),VALUE(MID($B19,17,2)),VALUE(MID($B19,15,2)))) | E19: =IF(LEN($B19)<45,"",VALUE(MID($B19,23,23))) | F19: =IF(LEN($B19)<46,"",MID($B19,46,1)) | G19: =IF(LEN($B19)<116,"",TRIM(MID($B19,82,35))) | H19: =IF($E19="","",$E19/IF(ttAmountUnit="Paise",1,100)) | I19: =IF($G19="","",IF($J19=0,"-- no match --",INDEX(Entries!$B$5:$B$104,$J19))) | J19: =IF($G19="","",SUMPRODUCT(MAX((Entries!$H$5:$H$104<>"")*ISNUMBER(SEARCH(Entries!$H$5:$H$104,$G19&""))*(ROW(Entries!$H$5:$H$104)-4))))
A20: 11 | C20: =IF(LEN($B20)<14,"",TRIM(MID($B20,1,14))) | D20: =IF(LEN($B20)<22,"",DATE(VALUE(MID($B20,19,4)),VALUE(MID($B20,17,2)),VALUE(MID($B20,15,2)))) | E20: =IF(LEN($B20)<45,"",VALUE(MID($B20,23,23))) | F20: =IF(LEN($B20)<46,"",MID($B20,46,1)) | G20: =IF(LEN($B20)<116,"",TRIM(MID($B20,82,35))) | H20: =IF($E20="","",$E20/IF(ttAmountUnit="Paise",1,100)) | I20: =IF($G20="","",IF($J20=0,"-- no match --",INDEX(Entries!$B$5:$B$104,$J20))) | J20: =IF($G20="","",SUMPRODUCT(MAX((Entries!$H$5:$H$104<>"")*ISNUMBER(SEARCH(Entries!$H$5:$H$104,$G20&""))*(ROW(Entries!$H$5:$H$104)-4))))
A21: 12 | C21: =IF(LEN($B21)<14,"",TRIM(MID($B21,1,14))) | D21: =IF(LEN($B21)<22,"",DATE(VALUE(MID($B21,19,4)),VALUE(MID($B21,17,2)),VALUE(MID($B21,15,2)))) | E21: =IF(LEN($B21)<45,"",VALUE(MID($B21,23,23))) | F21: =IF(LEN($B21)<46,"",MID($B21,46,1)) | G21: =IF(LEN($B21)<116,"",TRIM(MID($B21,82,35))) | H21: =IF($E21="","",$E21/IF(ttAmountUnit="Paise",1,100)) | I21: =IF($G21="","",IF($J21=0,"-- no match --",INDEX(Entries!$B$5:$B$104,$J21))) | J21: =IF($G21="","",SUMPRODUCT(MAX((Entries!$H$5:$H$104<>"")*ISNUMBER(SEARCH(Entries!$H$5:$H$104,$G21&""))*(ROW(Entries!$H$5:$H$104)-4))))
... A109: 100 | C109: =IF(LEN($B109)<14,"",TRIM(MID($B109,1,14))) | D109: =IF(LEN($B109)<22,"",DATE(VALUE(MID($B109,19,4)),VALUE(MID($B109,17,2)),VALUE(MID($B109,15,2)))) | E109: =IF(LEN($B109)<45,"",VALUE(MID($B109,23,23))) | F109: =IF(LEN($B109)<46,"",MID($B109,46,1)) | G109: =IF(LEN($B109)<116,"",TRIM(MID($B109,82,35))) | H109: =IF($E109="","",$E109/IF(ttAmountUnit="Paise",1,100)) | I109: =IF($G109="","",IF($J109=0,"-- no match --",INDEX(Entries!$B$5:$B$104,$J109))) | J109: =IF($G109="","",SUMPRODUCT(MAX((Entries!$H$5:$H$104<>"")*ISNUMBER(SEARCH(Entries!$H$5:$H$104,$G109&""))*(ROW(Entries!$H$5:$H$104)-4))))

Sheet Text Output
A1: TEXT OUTPUT (works without macros)
A2: The same records, built by formula. Copy them into Notepad and save.
A3: 1. Set the value date and the amounts as usual, on the Dashboard and Entries sheets.
A4: 2. Select the filled cells in column A below, from A6 down to the last one with text.
A5: 3. Copy, then paste into Notepad.
A6: 4. Save from Notepad as the file name shown on the Dashboard, with Encoding set to ANSI.
A8: Record (each line is exactly 186 characters) | B8: Length | C8: Row
A9: =IF($C9="","",LEFT(INDEX(Entries!$C$5:$C$104,$C9)&REPT(" ",14),14)&TEXT(ttValueDate,"ddmmyyyy")&TEXT(INDEX(Entries!$E$5:$E$104,$C9)*IF(ttAmountUnit="Paise",1,100),REPT("0",23))&INDEX(Entries!$D$5:$D$104,$C9)&"0"&TEXT(ttValueDate,"ddmmyyyy")&REPT(" ",26)&LEFT(SUBSTITUTE(SUBSTITUTE(SUBSTITUTE(SUBSTITUTE(SUBSTITUTE(SUBSTITUTE(INDEX(Entries!$F$5:$F$104,$C9),"{DDMMYYYY}",TEXT(ttValueDate,"ddmmyyyy")),"{DDMMYY}",TEXT(ttValueDate,"ddmmyy")),"{YYYY}",TEXT(ttValueDate,"yyyy")),"{DD}",TEXT(ttValueDate,"dd")),"{MM}",TEXT(ttValueDate,"mm")),"{YY}",TEXT(ttValueDate,"yy"))&REPT(" ",35),35)&REPT(" ",70)) | B9: =IF($A9="","",LEN($A9)) | C9: =IFERROR(MATCH(1,Entries!$I$5:$I$104,0),"")
A10: =IF($C10="","",LEFT(INDEX(Entries!$C$5:$C$104,$C10)&REPT(" ",14),14)&TEXT(ttValueDate,"ddmmyyyy")&TEXT(INDEX(Entries!$E$5:$E$104,$C10)*IF(ttAmountUnit="Paise",1,100),REPT("0",23))&INDEX(Entries!$D$5:$D$104,$C10)&"0"&TEXT(ttValueDate,"ddmmyyyy")&REPT(" ",26)&LEFT(SUBSTITUTE(SUBSTITUTE(SUBSTITUTE(SUBSTITUTE(SUBSTITUTE(SUBSTITUTE(INDEX(Entries!$F$5:$F$104,$C10),"{DDMMYYYY}",TEXT(ttValueDate,"ddmmyyyy")),"{DDMMYY}",TEXT(ttValueDate,"ddmmyy")),"{YYYY}",TEXT(ttValueDate,"yyyy")),"{DD}",TEXT(ttValueDate,"dd")),"{MM}",TEXT(ttValueDate,"mm")),"{YY}",TEXT(ttValueDate,"yy"))&REPT(" ",35),35)&REPT(" ",70)) | B10: =IF($A10="","",LEN($A10)) | C10: =IFERROR(MATCH(2,Entries!$I$5:$I$104,0),"")
A11: =IF($C11="","",LEFT(INDEX(Entries!$C$5:$C$104,$C11)&REPT(" ",14),14)&TEXT(ttValueDate,"ddmmyyyy")&TEXT(INDEX(Entries!$E$5:$E$104,$C11)*IF(ttAmountUnit="Paise",1,100),REPT("0",23))&INDEX(Entries!$D$5:$D$104,$C11)&"0"&TEXT(ttValueDate,"ddmmyyyy")&REPT(" ",26)&LEFT(SUBSTITUTE(SUBSTITUTE(SUBSTITUTE(SUBSTITUTE(SUBSTITUTE(SUBSTITUTE(INDEX(Entries!$F$5:$F$104,$C11),"{DDMMYYYY}",TEXT(ttValueDate,"ddmmyyyy")),"{DDMMYY}",TEXT(ttValueDate,"ddmmyy")),"{YYYY}",TEXT(ttValueDate,"yyyy")),"{DD}",TEXT(ttValueDate,"dd")),"{MM}",TEXT(ttValueDate,"mm")),"{YY}",TEXT(ttValueDate,"yy"))&REPT(" ",35),35)&REPT(" ",70)) | B11: =IF($A11="","",LEN($A11)) | C11: =IFERROR(MATCH(3,Entries!$I$5:$I$104,0),"")
A12: =IF($C12="","",LEFT(INDEX(Entries!$C$5:$C$104,$C12)&REPT(" ",14),14)&TEXT(ttValueDate,"ddmmyyyy")&TEXT(INDEX(Entries!$E$5:$E$104,$C12)*IF(ttAmountUnit="Paise",1,100),REPT("0",23))&INDEX(Entries!$D$5:$D$104,$C12)&"0"&TEXT(ttValueDate,"ddmmyyyy")&REPT(" ",26)&LEFT(SUBSTITUTE(SUBSTITUTE(SUBSTITUTE(SUBSTITUTE(SUBSTITUTE(SUBSTITUTE(INDEX(Entries!$F$5:$F$104,$C12),"{DDMMYYYY}",TEXT(ttValueDate,"ddmmyyyy")),"{DDMMYY}",TEXT(ttValueDate,"ddmmyy")),"{YYYY}",TEXT(ttValueDate,"yyyy")),"{DD}",TEXT(ttValueDate,"dd")),"{MM}",TEXT(ttValueDate,"mm")),"{YY}",TEXT(ttValueDate,"yy"))&REPT(" ",35),35)&REPT(" ",70)) | B12: =IF($A12="","",LEN($A12)) | C12: =IFERROR(MATCH(4,Entries!$I$5:$I$104,0),"")
A13: =IF($C13="","",LEFT(INDEX(Entries!$C$5:$C$104,$C13)&REPT(" ",14),14)&TEXT(ttValueDate,"ddmmyyyy")&TEXT(INDEX(Entries!$E$5:$E$104,$C13)*IF(ttAmountUnit="Paise",1,100),REPT("0",23))&INDEX(Entries!$D$5:$D$104,$C13)&"0"&TEXT(ttValueDate,"ddmmyyyy")&REPT(" ",26)&LEFT(SUBSTITUTE(SUBSTITUTE(SUBSTITUTE(SUBSTITUTE(SUBSTITUTE(SUBSTITUTE(INDEX(Entries!$F$5:$F$104,$C13),"{DDMMYYYY}",TEXT(ttValueDate,"ddmmyyyy")),"{DDMMYY}",TEXT(ttValueDate,"ddmmyy")),"{YYYY}",TEXT(ttValueDate,"yyyy")),"{DD}",TEXT(ttValueDate,"dd")),"{MM}",TEXT(ttValueDate,"mm")),"{YY}",TEXT(ttValueDate,"yy"))&REPT(" ",35),35)&REPT(" ",70)) | B13: =IF($A13="","",LEN($A13)) | C13: =IFERROR(MATCH(5,Entries!$I$5:$I$104,0),"")
A14: =IF($C14="","",LEFT(INDEX(Entries!$C$5:$C$104,$C14)&REPT(" ",14),14)&TEXT(ttValueDate,"ddmmyyyy")&TEXT(INDEX(Entries!$E$5:$E$104,$C14)*IF(ttAmountUnit="Paise",1,100),REPT("0",23))&INDEX(Entries!$D$5:$D$104,$C14)&"0"&TEXT(ttValueDate,"ddmmyyyy")&REPT(" ",26)&LEFT(SUBSTITUTE(SUBSTITUTE(SUBSTITUTE(SUBSTITUTE(SUBSTITUTE(SUBSTITUTE(INDEX(Entries!$F$5:$F$104,$C14),"{DDMMYYYY}",TEXT(ttValueDate,"ddmmyyyy")),"{DDMMYY}",TEXT(ttValueDate,"ddmmyy")),"{YYYY}",TEXT(ttValueDate,"yyyy")),"{DD}",TEXT(ttValueDate,"dd")),"{MM}",TEXT(ttValueDate,"mm")),"{YY}",TEXT(ttValueDate,"yy"))&REPT(" ",35),35)&REPT(" ",70)) | B14: =IF($A14="","",LEN($A14)) | C14: =IFERROR(MATCH(6,Entries!$I$5:$I$104,0),"")
A15: =IF($C15="","",LEFT(INDEX(Entries!$C$5:$C$104,$C15)&REPT(" ",14),14)&TEXT(ttValueDate,"ddmmyyyy")&TEXT(INDEX(Entries!$E$5:$E$104,$C15)*IF(ttAmountUnit="Paise",1,100),REPT("0",23))&INDEX(Entries!$D$5:$D$104,$C15)&"0"&TEXT(ttValueDate,"ddmmyyyy")&REPT(" ",26)&LEFT(SUBSTITUTE(SUBSTITUTE(SUBSTITUTE(SUBSTITUTE(SUBSTITUTE(SUBSTITUTE(INDEX(Entries!$F$5:$F$104,$C15),"{DDMMYYYY}",TEXT(ttValueDate,"ddmmyyyy")),"{DDMMYY}",TEXT(ttValueDate,"ddmmyy")),"{YYYY}",TEXT(ttValueDate,"yyyy")),"{DD}",TEXT(ttValueDate,"dd")),"{MM}",TEXT(ttValueDate,"mm")),"{YY}",TEXT(ttValueDate,"yy"))&REPT(" ",35),35)&REPT(" ",70)) | B15: =IF($A15="","",LEN($A15)) | C15: =IFERROR(MATCH(7,Entries!$I$5:$I$104,0),"")
A16: =IF($C16="","",LEFT(INDEX(Entries!$C$5:$C$104,$C16)&REPT(" ",14),14)&TEXT(ttValueDate,"ddmmyyyy")&TEXT(INDEX(Entries!$E$5:$E$104,$C16)*IF(ttAmountUnit="Paise",1,100),REPT("0",23))&INDEX(Entries!$D$5:$D$104,$C16)&"0"&TEXT(ttValueDate,"ddmmyyyy")&REPT(" ",26)&LEFT(SUBSTITUTE(SUBSTITUTE(SUBSTITUTE(SUBSTITUTE(SUBSTITUTE(SUBSTITUTE(INDEX(Entries!$F$5:$F$104,$C16),"{DDMMYYYY}",TEXT(ttValueDate,"ddmmyyyy")),"{DDMMYY}",TEXT(ttValueDate,"ddmmyy")),"{YYYY}",TEXT(ttValueDate,"yyyy")),"{DD}",TEXT(ttValueDate,"dd")),"{MM}",TEXT(ttValueDate,"mm")),"{YY}",TEXT(ttValueDate,"yy"))&REPT(" ",35),35)&REPT(" ",70)) | B16: =IF($A16="","",LEN($A16)) | C16: =IFERROR(MATCH(8,Entries!$I$5:$I$104,0),"")
A17: =IF($C17="","",LEFT(INDEX(Entries!$C$5:$C$104,$C17)&REPT(" ",14),14)&TEXT(ttValueDate,"ddmmyyyy")&TEXT(INDEX(Entries!$E$5:$E$104,$C17)*IF(ttAmountUnit="Paise",1,100),REPT("0",23))&INDEX(Entries!$D$5:$D$104,$C17)&"0"&TEXT(ttValueDate,"ddmmyyyy")&REPT(" ",26)&LEFT(SUBSTITUTE(SUBSTITUTE(SUBSTITUTE(SUBSTITUTE(SUBSTITUTE(SUBSTITUTE(INDEX(Entries!$F$5:$F$104,$C17),"{DDMMYYYY}",TEXT(ttValueDate,"ddmmyyyy")),"{DDMMYY}",TEXT(ttValueDate,"ddmmyy")),"{YYYY}",TEXT(ttValueDate,"yyyy")),"{DD}",TEXT(ttValueDate,"dd")),"{MM}",TEXT(ttValueDate,"mm")),"{YY}",TEXT(ttValueDate,"yy"))&REPT(" ",35),35)&REPT(" ",70)) | B17: =IF($A17="","",LEN($A17)) | C17: =IFERROR(MATCH(9,Entries!$I$5:$I$104,0),"")
A18: =IF($C18="","",LEFT(INDEX(Entries!$C$5:$C$104,$C18)&REPT(" ",14),14)&TEXT(ttValueDate,"ddmmyyyy")&TEXT(INDEX(Entries!$E$5:$E$104,$C18)*IF(ttAmountUnit="Paise",1,100),REPT("0",23))&INDEX(Entries!$D$5:$D$104,$C18)&"0"&TEXT(ttValueDate,"ddmmyyyy")&REPT(" ",26)&LEFT(SUBSTITUTE(SUBSTITUTE(SUBSTITUTE(SUBSTITUTE(SUBSTITUTE(SUBSTITUTE(INDEX(Entries!$F$5:$F$104,$C18),"{DDMMYYYY}",TEXT(ttValueDate,"ddmmyyyy")),"{DDMMYY}",TEXT(ttValueDate,"ddmmyy")),"{YYYY}",TEXT(ttValueDate,"yyyy")),"{DD}",TEXT(ttValueDate,"dd")),"{MM}",TEXT(ttValueDate,"mm")),"{YY}",TEXT(ttValueDate,"yy"))&REPT(" ",35),35)&REPT(" ",70)) | B18: =IF($A18="","",LEN($A18)) | C18: =IFERROR(MATCH(10,Entries!$I$5:$I$104,0),"")
A19: =IF($C19="","",LEFT(INDEX(Entries!$C$5:$C$104,$C19)&REPT(" ",14),14)&TEXT(ttValueDate,"ddmmyyyy")&TEXT(INDEX(Entries!$E$5:$E$104,$C19)*IF(ttAmountUnit="Paise",1,100),REPT("0",23))&INDEX(Entries!$D$5:$D$104,$C19)&"0"&TEXT(ttValueDate,"ddmmyyyy")&REPT(" ",26)&LEFT(SUBSTITUTE(SUBSTITUTE(SUBSTITUTE(SUBSTITUTE(SUBSTITUTE(SUBSTITUTE(INDEX(Entries!$F$5:$F$104,$C19),"{DDMMYYYY}",TEXT(ttValueDate,"ddmmyyyy")),"{DDMMYY}",TEXT(ttValueDate,"ddmmyy")),"{YYYY}",TEXT(ttValueDate,"yyyy")),"{DD}",TEXT(ttValueDate,"dd")),"{MM}",TEXT(ttValueDate,"mm")),"{YY}",TEXT(ttValueDate,"yy"))&REPT(" ",35),35)&REPT(" ",70)) | B19: =IF($A19="","",LEN($A19)) | C19: =IFERROR(MATCH(11,Entries!$I$5:$I$104,0),"")
A20: =IF($C20="","",LEFT(INDEX(Entries!$C$5:$C$104,$C20)&REPT(" ",14),14)&TEXT(ttValueDate,"ddmmyyyy")&TEXT(INDEX(Entries!$E$5:$E$104,$C20)*IF(ttAmountUnit="Paise",1,100),REPT("0",23))&INDEX(Entries!$D$5:$D$104,$C20)&"0"&TEXT(ttValueDate,"ddmmyyyy")&REPT(" ",26)&LEFT(SUBSTITUTE(SUBSTITUTE(SUBSTITUTE(SUBSTITUTE(SUBSTITUTE(SUBSTITUTE(INDEX(Entries!$F$5:$F$104,$C20),"{DDMMYYYY}",TEXT(ttValueDate,"ddmmyyyy")),"{DDMMYY}",TEXT(ttValueDate,"ddmmyy")),"{YYYY}",TEXT(ttValueDate,"yyyy")),"{DD}",TEXT(ttValueDate,"dd")),"{MM}",TEXT(ttValueDate,"mm")),"{YY}",TEXT(ttValueDate,"yy"))&REPT(" ",35),35)&REPT(" ",70)) | B20: =IF($A20="","",LEN($A20)) | C20: =IFERROR(MATCH(12,Entries!$I$5:$I$104,0),"")
A21: =IF($C21="","",LEFT(INDEX(Entries!$C$5:$C$104,$C21)&REPT(" ",14),14)&TEXT(ttValueDate,"ddmmyyyy")&TEXT(INDEX(Entries!$E$5:$E$104,$C21)*IF(ttAmountUnit="Paise",1,100),REPT("0",23))&INDEX(Entries!$D$5:$D$104,$C21)&"0"&TEXT(ttValueDate,"ddmmyyyy")&REPT(" ",26)&LEFT(SUBSTITUTE(SUBSTITUTE(SUBSTITUTE(SUBSTITUTE(SUBSTITUTE(SUBSTITUTE(INDEX(Entries!$F$5:$F$104,$C21),"{DDMMYYYY}",TEXT(ttValueDate,"ddmmyyyy")),"{DDMMYY}",TEXT(ttValueDate,"ddmmyy")),"{YYYY}",TEXT(ttValueDate,"yyyy")),"{DD}",TEXT(ttValueDate,"dd")),"{MM}",TEXT(ttValueDate,"mm")),"{YY}",TEXT(ttValueDate,"yy"))&REPT(" ",35),35)&REPT(" ",70)) | B21: =IF($A21="","",LEN($A21)) | C21: =IFERROR(MATCH(13,Entries!$I$5:$I$104,0),"")
A22: =IF($C22="","",LEFT(INDEX(Entries!$C$5:$C$104,$C22)&REPT(" ",14),14)&TEXT(ttValueDate,"ddmmyyyy")&TEXT(INDEX(Entries!$E$5:$E$104,$C22)*IF(ttAmountUnit="Paise",1,100),REPT("0",23))&INDEX(Entries!$D$5:$D$104,$C22)&"0"&TEXT(ttValueDate,"ddmmyyyy")&REPT(" ",26)&LEFT(SUBSTITUTE(SUBSTITUTE(SUBSTITUTE(SUBSTITUTE(SUBSTITUTE(SUBSTITUTE(INDEX(Entries!$F$5:$F$104,$C22),"{DDMMYYYY}",TEXT(ttValueDate,"ddmmyyyy")),"{DDMMYY}",TEXT(ttValueDate,"ddmmyy")),"{YYYY}",TEXT(ttValueDate,"yyyy")),"{DD}",TEXT(ttValueDate,"dd")),"{MM}",TEXT(ttValueDate,"mm")),"{YY}",TEXT(ttValueDate,"yy"))&REPT(" ",35),35)&REPT(" ",70)) | B22: =IF($A22="","",LEN($A22)) | C22: =IFERROR(MATCH(14,Entries!$I$5:$I$104,0),"")
A23: =IF($C23="","",LEFT(INDEX(Entries!$C$5:$C$104,$C23)&REPT(" ",14),14)&TEXT(ttValueDate,"ddmmyyyy")&TEXT(INDEX(Entries!$E$5:$E$104,$C23)*IF(ttAmountUnit="Paise",1,100),REPT("0",23))&INDEX(Entries!$D$5:$D$104,$C23)&"0"&TEXT(ttValueDate,"ddmmyyyy")&REPT(" ",26)&LEFT(SUBSTITUTE(SUBSTITUTE(SUBSTITUTE(SUBSTITUTE(SUBSTITUTE(SUBSTITUTE(INDEX(Entries!$F$5:$F$104,$C23),"{DDMMYYYY}",TEXT(ttValueDate,"ddmmyyyy")),"{DDMMYY}",TEXT(ttValueDate,"ddmmyy")),"{YYYY}",TEXT(ttValueDate,"yyyy")),"{DD}",TEXT(ttValueDate,"dd")),"{MM}",TEXT(ttValueDate,"mm")),"{YY}",TEXT(ttValueDate,"yy"))&REPT(" ",35),35)&REPT(" ",70)) | B23: =IF($A23="","",LEN($A23)) | C23: =IFERROR(MATCH(15,Entries!$I$5:$I$104,0),"")
A24: =IF($C24="","",LEFT(INDEX(Entries!$C$5:$C$104,$C24)&REPT(" ",14),14)&TEXT(ttValueDate,"ddmmyyyy")&TEXT(INDEX(Entries!$E$5:$E$104,$C24)*IF(ttAmountUnit="Paise",1,100),REPT("0",23))&INDEX(Entries!$D$5:$D$104,$C24)&"0"&TEXT(ttValueDate,"ddmmyyyy")&REPT(" ",26)&LEFT(SUBSTITUTE(SUBSTITUTE(SUBSTITUTE(SUBSTITUTE(SUBSTITUTE(SUBSTITUTE(INDEX(Entries!$F$5:$F$104,$C24),"{DDMMYYYY}",TEXT(ttValueDate,"ddmmyyyy")),"{DDMMYY}",TEXT(ttValueDate,"ddmmyy")),"{YYYY}",TEXT(ttValueDate,"yyyy")),"{DD}",TEXT(ttValueDate,"dd")),"{MM}",TEXT(ttValueDate,"mm")),"{YY}",TEXT(ttValueDate,"yy"))&REPT(" ",35),35)&REPT(" ",70)) | B24: =IF($A24="","",LEN($A24)) | C24: =IFERROR(MATCH(16,Entries!$I$5:$I$104,0),"")
A25: =IF($C25="","",LEFT(INDEX(Entries!$C$5:$C$104,$C25)&REPT(" ",14),14)&TEXT(ttValueDate,"ddmmyyyy")&TEXT(INDEX(Entries!$E$5:$E$104,$C25)*IF(ttAmountUnit="Paise",1,100),REPT("0",23))&INDEX(Entries!$D$5:$D$104,$C25)&"0"&TEXT(ttValueDate,"ddmmyyyy")&REPT(" ",26)&LEFT(SUBSTITUTE(SUBSTITUTE(SUBSTITUTE(SUBSTITUTE(SUBSTITUTE(SUBSTITUTE(INDEX(Entries!$F$5:$F$104,$C25),"{DDMMYYYY}",TEXT(ttValueDate,"ddmmyyyy")),"{DDMMYY}",TEXT(ttValueDate,"ddmmyy")),"{YYYY}",TEXT(ttValueDate,"yyyy")),"{DD}",TEXT(ttValueDate,"dd")),"{MM}",TEXT(ttValueDate,"mm")),"{YY}",TEXT(ttValueDate,"yy"))&REPT(" ",35),35)&REPT(" ",70)) | B25: =IF($A25="","",LEN($A25)) | C25: =IFERROR(MATCH(17,Entries!$I$5:$I$104,0),"")
A26: =IF($C26="","",LEFT(INDEX(Entries!$C$5:$C$104,$C26)&REPT(" ",14),14)&TEXT(ttValueDate,"ddmmyyyy")&TEXT(INDEX(Entries!$E$5:$E$104,$C26)*IF(ttAmountUnit="Paise",1,100),REPT("0",23))&INDEX(Entries!$D$5:$D$104,$C26)&"0"&TEXT(ttValueDate,"ddmmyyyy")&REPT(" ",26)&LEFT(SUBSTITUTE(SUBSTITUTE(SUBSTITUTE(SUBSTITUTE(SUBSTITUTE(SUBSTITUTE(INDEX(Entries!$F$5:$F$104,$C26),"{DDMMYYYY}",TEXT(ttValueDate,"ddmmyyyy")),"{DDMMYY}",TEXT(ttValueDate,"ddmmyy")),"{YYYY}",TEXT(ttValueDate,"yyyy")),"{DD}",TEXT(ttValueDate,"dd")),"{MM}",TEXT(ttValueDate,"mm")),"{YY}",TEXT(ttValueDate,"yy"))&REPT(" ",35),35)&REPT(" ",70)) | B26: =IF($A26="","",LEN($A26)) | C26: =IFERROR(MATCH(18,Entries!$I$5:$I$104,0),"")
A27: =IF($C27="","",LEFT(INDEX(Entries!$C$5:$C$104,$C27)&REPT(" ",14),14)&TEXT(ttValueDate,"ddmmyyyy")&TEXT(INDEX(Entries!$E$5:$E$104,$C27)*IF(ttAmountUnit="Paise",1,100),REPT("0",23))&INDEX(Entries!$D$5:$D$104,$C27)&"0"&TEXT(ttValueDate,"ddmmyyyy")&REPT(" ",26)&LEFT(SUBSTITUTE(SUBSTITUTE(SUBSTITUTE(SUBSTITUTE(SUBSTITUTE(SUBSTITUTE(INDEX(Entries!$F$5:$F$104,$C27),"{DDMMYYYY}",TEXT(ttValueDate,"ddmmyyyy")),"{DDMMYY}",TEXT(ttValueDate,"ddmmyy")),"{YYYY}",TEXT(ttValueDate,"yyyy")),"{DD}",TEXT(ttValueDate,"dd")),"{MM}",TEXT(ttValueDate,"mm")),"{YY}",TEXT(ttValueDate,"yy"))&REPT(" ",35),35)&REPT(" ",70)) | B27: =IF($A27="","",LEN($A27)) | C27: =IFERROR(MATCH(19,Entries!$I$5:$I$104,0),"")
A28: =IF($C28="","",LEFT(INDEX(Entries!$C$5:$C$104,$C28)&REPT(" ",14),14)&TEXT(ttValueDate,"ddmmyyyy")&TEXT(INDEX(Entries!$E$5:$E$104,$C28)*IF(ttAmountUnit="Paise",1,100),REPT("0",23))&INDEX(Entries!$D$5:$D$104,$C28)&"0"&TEXT(ttValueDate,"ddmmyyyy")&REPT(" ",26)&LEFT(SUBSTITUTE(SUBSTITUTE(SUBSTITUTE(SUBSTITUTE(SUBSTITUTE(SUBSTITUTE(INDEX(Entries!$F$5:$F$104,$C28),"{DDMMYYYY}",TEXT(ttValueDate,"ddmmyyyy")),"{DDMMYY}",TEXT(ttValueDate,"ddmmyy")),"{YYYY}",TEXT(ttValueDate,"yyyy")),"{DD}",TEXT(ttValueDate,"dd")),"{MM}",TEXT(ttValueDate,"mm")),"{YY}",TEXT(ttValueDate,"yy"))&REPT(" ",35),35)&REPT(" ",70)) | B28: =IF($A28="","",LEN($A28)) | C28: =IFERROR(MATCH(20,Entries!$I$5:$I$104,0),"")
A29: =IF($C29="","",LEFT(INDEX(Entries!$C$5:$C$104,$C29)&REPT(" ",14),14)&TEXT(ttValueDate,"ddmmyyyy")&TEXT(INDEX(Entries!$E$5:$E$104,$C29)*IF(ttAmountUnit="Paise",1,100),REPT("0",23))&INDEX(Entries!$D$5:$D$104,$C29)&"0"&TEXT(ttValueDate,"ddmmyyyy")&REPT(" ",26)&LEFT(SUBSTITUTE(SUBSTITUTE(SUBSTITUTE(SUBSTITUTE(SUBSTITUTE(SUBSTITUTE(INDEX(Entries!$F$5:$F$104,$C29),"{DDMMYYYY}",TEXT(ttValueDate,"ddmmyyyy")),"{DDMMYY}",TEXT(ttValueDate,"ddmmyy")),"{YYYY}",TEXT(ttValueDate,"yyyy")),"{DD}",TEXT(ttValueDate,"dd")),"{MM}",TEXT(ttValueDate,"mm")),"{YY}",TEXT(ttValueDate,"yy"))&REPT(" ",35),35)&REPT(" ",70)) | B29: =IF($A29="","",LEN($A29)) | C29: =IFERROR(MATCH(21,Entries!$I$5:$I$104,0),"")
A30: =IF($C30="","",LEFT(INDEX(Entries!$C$5:$C$104,$C30)&REPT(" ",14),14)&TEXT(ttValueDate,"ddmmyyyy")&TEXT(INDEX(Entries!$E$5:$E$104,$C30)*IF(ttAmountUnit="Paise",1,100),REPT("0",23))&INDEX(Entries!$D$5:$D$104,$C30)&"0"&TEXT(ttValueDate,"ddmmyyyy")&REPT(" ",26)&LEFT(SUBSTITUTE(SUBSTITUTE(SUBSTITUTE(SUBSTITUTE(SUBSTITUTE(SUBSTITUTE(INDEX(Entries!$F$5:$F$104,$C30),"{DDMMYYYY}",TEXT(ttValueDate,"ddmmyyyy")),"{DDMMYY}",TEXT(ttValueDate,"ddmmyy")),"{YYYY}",TEXT(ttValueDate,"yyyy")),"{DD}",TEXT(ttValueDate,"dd")),"{MM}",TEXT(ttValueDate,"mm")),"{YY}",TEXT(ttValueDate,"yy"))&REPT(" ",35),35)&REPT(" ",70)) | B30: =IF($A30="","",LEN($A30)) | C30: =IFERROR(MATCH(22,Entries!$I$5:$I$104,0),"")
A31: =IF($C31="","",LEFT(INDEX(Entries!$C$5:$C$104,$C31)&REPT(" ",14),14)&TEXT(ttValueDate,"ddmmyyyy")&TEXT(INDEX(Entries!$E$5:$E$104,$C31)*IF(ttAmountUnit="Paise",1,100),REPT("0",23))&INDEX(Entries!$D$5:$D$104,$C31)&"0"&TEXT(ttValueDate,"ddmmyyyy")&REPT(" ",26)&LEFT(SUBSTITUTE(SUBSTITUTE(SUBSTITUTE(SUBSTITUTE(SUBSTITUTE(SUBSTITUTE(INDEX(Entries!$F$5:$F$104,$C31),"{DDMMYYYY}",TEXT(ttValueDate,"ddmmyyyy")),"{DDMMYY}",TEXT(ttValueDate,"ddmmyy")),"{YYYY}",TEXT(ttValueDate,"yyyy")),"{DD}",TEXT(ttValueDate,"dd")),"{MM}",TEXT(ttValueDate,"mm")),"{YY}",TEXT(ttValueDate,"yy"))&REPT(" ",35),35)&REPT(" ",70)) | B31: =IF($A31="","",LEN($A31)) | C31: =IFERROR(MATCH(23,Entries!$I$5:$I$104,0),"")
A32: =IF($C32="","",LEFT(INDEX(Entries!$C$5:$C$104,$C32)&REPT(" ",14),14)&TEXT(ttValueDate,"ddmmyyyy")&TEXT(INDEX(Entries!$E$5:$E$104,$C32)*IF(ttAmountUnit="Paise",1,100),REPT("0",23))&INDEX(Entries!$D$5:$D$104,$C32)&"0"&TEXT(ttValueDate,"ddmmyyyy")&REPT(" ",26)&LEFT(SUBSTITUTE(SUBSTITUTE(SUBSTITUTE(SUBSTITUTE(SUBSTITUTE(SUBSTITUTE(INDEX(Entries!$F$5:$F$104,$C32),"{DDMMYYYY}",TEXT(ttValueDate,"ddmmyyyy")),"{DDMMYY}",TEXT(ttValueDate,"ddmmyy")),"{YYYY}",TEXT(ttValueDate,"yyyy")),"{DD}",TEXT(ttValueDate,"dd")),"{MM}",TEXT(ttValueDate,"mm")),"{YY}",TEXT(ttValueDate,"yy"))&REPT(" ",35),35)&REPT(" ",70)) | B32: =IF($A32="","",LEN($A32)) | C32: =IFERROR(MATCH(24,Entries!$I$5:$I$104,0),"")
A33: =IF($C33="","",LEFT(INDEX(Entries!$C$5:$C$104,$C33)&REPT(" ",14),14)&TEXT(ttValueDate,"ddmmyyyy")&TEXT(INDEX(Entries!$E$5:$E$104,$C33)*IF(ttAmountUnit="Paise",1,100),REPT("0",23))&INDEX(Entries!$D$5:$D$104,$C33)&"0"&TEXT(ttValueDate,"ddmmyyyy")&REPT(" ",26)&LEFT(SUBSTITUTE(SUBSTITUTE(SUBSTITUTE(SUBSTITUTE(SUBSTITUTE(SUBSTITUTE(INDEX(Entries!$F$5:$F$104,$C33),"{DDMMYYYY}",TEXT(ttValueDate,"ddmmyyyy")),"{DDMMYY}",TEXT(ttValueDate,"ddmmyy")),"{YYYY}",TEXT(ttValueDate,"yyyy")),"{DD}",TEXT(ttValueDate,"dd")),"{MM}",TEXT(ttValueDate,"mm")),"{YY}",TEXT(ttValueDate,"yy"))&REPT(" ",35),35)&REPT(" ",70)) | B33: =IF($A33="","",LEN($A33)) | C33: =IFERROR(MATCH(25,Entries!$I$5:$I$104,0),"")
A34: =IF($C34="","",LEFT(INDEX(Entries!$C$5:$C$104,$C34)&REPT(" ",14),14)&TEXT(ttValueDate,"ddmmyyyy")&TEXT(INDEX(Entries!$E$5:$E$104,$C34)*IF(ttAmountUnit="Paise",1,100),REPT("0",23))&INDEX(Entries!$D$5:$D$104,$C34)&"0"&TEXT(ttValueDate,"ddmmyyyy")&REPT(" ",26)&LEFT(SUBSTITUTE(SUBSTITUTE(SUBSTITUTE(SUBSTITUTE(SUBSTITUTE(SUBSTITUTE(INDEX(Entries!$F$5:$F$104,$C34),"{DDMMYYYY}",TEXT(ttValueDate,"ddmmyyyy")),"{DDMMYY}",TEXT(ttValueDate,"ddmmyy")),"{YYYY}",TEXT(ttValueDate,"yyyy")),"{DD}",TEXT(ttValueDate,"dd")),"{MM}",TEXT(ttValueDate,"mm")),"{YY}",TEXT(ttValueDate,"yy"))&REPT(" ",35),35)&REPT(" ",70)) | B34: =IF($A34="","",LEN($A34)) | C34: =IFERROR(MATCH(26,Entries!$I$5:$I$104,0),"")
A35: =IF($C35="","",LEFT(INDEX(Entries!$C$5:$C$104,$C35)&REPT(" ",14),14)&TEXT(ttValueDate,"ddmmyyyy")&TEXT(INDEX(Entries!$E$5:$E$104,$C35)*IF(ttAmountUnit="Paise",1,100),REPT("0",23))&INDEX(Entries!$D$5:$D$104,$C35)&"0"&TEXT(ttValueDate,"ddmmyyyy")&REPT(" ",26)&LEFT(SUBSTITUTE(SUBSTITUTE(SUBSTITUTE(SUBSTITUTE(SUBSTITUTE(SUBSTITUTE(INDEX(Entries!$F$5:$F$104,$C35),"{DDMMYYYY}",TEXT(ttValueDate,"ddmmyyyy")),"{DDMMYY}",TEXT(ttValueDate,"ddmmyy")),"{YYYY}",TEXT(ttValueDate,"yyyy")),"{DD}",TEXT(ttValueDate,"dd")),"{MM}",TEXT(ttValueDate,"mm")),"{YY}",TEXT(ttValueDate,"yy"))&REPT(" ",35),35)&REPT(" ",70)) | B35: =IF($A35="","",LEN($A35)) | C35: =IFERROR(MATCH(27,Entries!$I$5:$I$104,0),"")
A36: =IF($C36="","",LEFT(INDEX(Entries!$C$5:$C$104,$C36)&REPT(" ",14),14)&TEXT(ttValueDate,"ddmmyyyy")&TEXT(INDEX(Entries!$E$5:$E$104,$C36)*IF(ttAmountUnit="Paise",1,100),REPT("0",23))&INDEX(Entries!$D$5:$D$104,$C36)&"0"&TEXT(ttValueDate,"ddmmyyyy")&REPT(" ",26)&LEFT(SUBSTITUTE(SUBSTITUTE(SUBSTITUTE(SUBSTITUTE(SUBSTITUTE(SUBSTITUTE(INDEX(Entries!$F$5:$F$104,$C36),"{DDMMYYYY}",TEXT(ttValueDate,"ddmmyyyy")),"{DDMMYY}",TEXT(ttValueDate,"ddmmyy")),"{YYYY}",TEXT(ttValueDate,"yyyy")),"{DD}",TEXT(ttValueDate,"dd")),"{MM}",TEXT(ttValueDate,"mm")),"{YY}",TEXT(ttValueDate,"yy"))&REPT(" ",35),35)&REPT(" ",70)) | B36: =IF($A36="","",LEN($A36)) | C36: =IFERROR(MATCH(28,Entries!$I$5:$I$104,0),"")
A37: =IF($C37="","",LEFT(INDEX(Entries!$C$5:$C$104,$C37)&REPT(" ",14),14)&TEXT(ttValueDate,"ddmmyyyy")&TEXT(INDEX(Entries!$E$5:$E$104,$C37)*IF(ttAmountUnit="Paise",1,100),REPT("0",23))&INDEX(Entries!$D$5:$D$104,$C37)&"0"&TEXT(ttValueDate,"ddmmyyyy")&REPT(" ",26)&LEFT(SUBSTITUTE(SUBSTITUTE(SUBSTITUTE(SUBSTITUTE(SUBSTITUTE(SUBSTITUTE(INDEX(Entries!$F$5:$F$104,$C37),"{DDMMYYYY}",TEXT(ttValueDate,"ddmmyyyy")),"{DDMMYY}",TEXT(ttValueDate,"ddmmyy")),"{YYYY}",TEXT(ttValueDate,"yyyy")),"{DD}",TEXT(ttValueDate,"dd")),"{MM}",TEXT(ttValueDate,"mm")),"{YY}",TEXT(ttValueDate,"yy"))&REPT(" ",35),35)&REPT(" ",70)) | B37: =IF($A37="","",LEN($A37)) | C37: =IFERROR(MATCH(29,Entries!$I$5:$I$104,0),"")
A38: =IF($C38="","",LEFT(INDEX(Entries!$C$5:$C$104,$C38)&REPT(" ",14),14)&TEXT(ttValueDate,"ddmmyyyy")&TEXT(INDEX(Entries!$E$5:$E$104,$C38)*IF(ttAmountUnit="Paise",1,100),REPT("0",23))&INDEX(Entries!$D$5:$D$104,$C38)&"0"&TEXT(ttValueDate,"ddmmyyyy")&REPT(" ",26)&LEFT(SUBSTITUTE(SUBSTITUTE(SUBSTITUTE(SUBSTITUTE(SUBSTITUTE(SUBSTITUTE(INDEX(Entries!$F$5:$F$104,$C38),"{DDMMYYYY}",TEXT(ttValueDate,"ddmmyyyy")),"{DDMMYY}",TEXT(ttValueDate,"ddmmyy")),"{YYYY}",TEXT(ttValueDate,"yyyy")),"{DD}",TEXT(ttValueDate,"dd")),"{MM}",TEXT(ttValueDate,"mm")),"{YY}",TEXT(ttValueDate,"yy"))&REPT(" ",35),35)&REPT(" ",70)) | B38: =IF($A38="","",LEN($A38)) | C38: =IFERROR(MATCH(30,Entries!$I$5:$I$104,0),"")
A39: =IF($C39="","",LEFT(INDEX(Entries!$C$5:$C$104,$C39)&REPT(" ",14),14)&TEXT(ttValueDate,"ddmmyyyy")&TEXT(INDEX(Entries!$E$5:$E$104,$C39)*IF(ttAmountUnit="Paise",1,100),REPT("0",23))&INDEX(Entries!$D$5:$D$104,$C39)&"0"&TEXT(ttValueDate,"ddmmyyyy")&REPT(" ",26)&LEFT(SUBSTITUTE(SUBSTITUTE(SUBSTITUTE(SUBSTITUTE(SUBSTITUTE(SUBSTITUTE(INDEX(Entries!$F$5:$F$104,$C39),"{DDMMYYYY}",TEXT(ttValueDate,"ddmmyyyy")),"{DDMMYY}",TEXT(ttValueDate,"ddmmyy")),"{YYYY}",TEXT(ttValueDate,"yyyy")),"{DD}",TEXT(ttValueDate,"dd")),"{MM}",TEXT(ttValueDate,"mm")),"{YY}",TEXT(ttValueDate,"yy"))&REPT(" ",35),35)&REPT(" ",70)) | B39: =IF($A39="","",LEN($A39)) | C39: =IFERROR(MATCH(31,Entries!$I$5:$I$104,0),"")
A40: =IF($C40="","",LEFT(INDEX(Entries!$C$5:$C$104,$C40)&REPT(" ",14),14)&TEXT(ttValueDate,"ddmmyyyy")&TEXT(INDEX(Entries!$E$5:$E$104,$C40)*IF(ttAmountUnit="Paise",1,100),REPT("0",23))&INDEX(Entries!$D$5:$D$104,$C40)&"0"&TEXT(ttValueDate,"ddmmyyyy")&REPT(" ",26)&LEFT(SUBSTITUTE(SUBSTITUTE(SUBSTITUTE(SUBSTITUTE(SUBSTITUTE(SUBSTITUTE(INDEX(Entries!$F$5:$F$104,$C40),"{DDMMYYYY}",TEXT(ttValueDate,"ddmmyyyy")),"{DDMMYY}",TEXT(ttValueDate,"ddmmyy")),"{YYYY}",TEXT(ttValueDate,"yyyy")),"{DD}",TEXT(ttValueDate,"dd")),"{MM}",TEXT(ttValueDate,"mm")),"{YY}",TEXT(ttValueDate,"yy"))&REPT(" ",35),35)&REPT(" ",70)) | B40: =IF($A40="","",LEN($A40)) | C40: =IFERROR(MATCH(32,Entries!$I$5:$I$104,0),"")
A41: =IF($C41="","",LEFT(INDEX(Entries!$C$5:$C$104,$C41)&REPT(" ",14),14)&TEXT(ttValueDate,"ddmmyyyy")&TEXT(INDEX(Entries!$E$5:$E$104,$C41)*IF(ttAmountUnit="Paise",1,100),REPT("0",23))&INDEX(Entries!$D$5:$D$104,$C41)&"0"&TEXT(ttValueDate,"ddmmyyyy")&REPT(" ",26)&LEFT(SUBSTITUTE(SUBSTITUTE(SUBSTITUTE(SUBSTITUTE(SUBSTITUTE(SUBSTITUTE(INDEX(Entries!$F$5:$F$104,$C41),"{DDMMYYYY}",TEXT(ttValueDate,"ddmmyyyy")),"{DDMMYY}",TEXT(ttValueDate,"ddmmyy")),"{YYYY}",TEXT(ttValueDate,"yyyy")),"{DD}",TEXT(ttValueDate,"dd")),"{MM}",TEXT(ttValueDate,"mm")),"{YY}",TEXT(ttValueDate,"yy"))&REPT(" ",35),35)&REPT(" ",70)) | B41: =IF($A41="","",LEN($A41)) | C41: =IFERROR(MATCH(33,Entries!$I$5:$I$104,0),"")
...

Sheet Config
A1: CONFIG
A2: Settings that rarely change. The daily inputs live on the Dashboard.
B4: Setting | C4: Value | D4: What it does
B5: Amount column is entered as | C5: Paise | D5: Paise: the Amount column is the figure exactly as the settlement report shows it, with the last two digits being the paise, so 47400 means 474.00. Rupees: type 474.00 instead. The Reads as (INR) column on Entries shows the effect.
B6: File name pattern | C6: PROPELG_TTUM_{DDMMYYYY}.txt | D6: Tokens are replaced with the file-name date shown on the Dashboard.
B7: File-name date offset (days) | C7: 1 | D7: The bank sample is dated one day after the value date it carries, so this is 1. Set 0 to use the value date itself.
B8: Block generation when out of balance | C8: Yes | D8: Yes stops the file when total debit does not equal total credit. No asks first and lets you continue.
B9: Write a line break after the last record | C9: No | D9: No matches the bank's sample file, which ends immediately after the last record.
B10: Input folder | D10: The folder the settlement system drops its file into. Import Latest Input File takes the newest matching file from here. Leave blank to be asked each time.
B11: Input file name pattern | C11: NET_MERPAY_PROPELG*.txt | D11: Which files in that folder count as settlement files. * stands for anything.
B12: Imported file sets the value date | C12: Yes | D12: Yes takes the value date from the file's own records. No keeps whatever is already on the Dashboard.

Sheet Log
A1: GENERATION LOG
A2: One row is added every time a file is written.
A3: Generated at | B3: Value date | C3: File date | D3: File name | E3: Records | F3: Total debit | G3: Total credit | H3: Balance | I3: User | J3: Full path

Sheet Layout
A1: RECORD LAYOUT
A2: Reference only - the macro builds every record to this layout.
B4: # | C4: Columns | D4: Field | E4: Length | F4: Content
B5: 1 | C5: 1-14 | D5: Account number | E5: 14 | F5: Left justified, padded on the right with spaces.
B6: 2 | C6: 15-22 | D6: Value date | E6: 8 | F6: DDMMYYYY.
B7: 3 | C7: 23-45 | D7: Amount | E7: 23 | F7: Whole paise, padded on the left with zeros. 20000 means 200.00.
B8: 4 | C8: 46 | D8: Transaction type | E8: 1 | F8: D for debit, C for credit.
B9: 5 | C9: 47-55 | D9: Value date | E9: 9 | F9: The same date again as 0 + DDMMYYYY.
B10: 6 | C10: 56-81 | D10: Filler | E10: 26 | F10: Spaces.
B11: 7 | C11: 82-116 | D11: Narration | E11: 35 | F11: Left justified, padded on the right with spaces.
B12: 8 | C12: 117-186 | D12: Filler | E12: 70 | F12: Spaces.
D13: Total | E13: 186 | F13: Records are separated by CR LF.
B15: Worked example - the bank's own file for value date 15-07-2026
B16: Amounts below are that day's figures; each line is exactly 186 characters.
B17: 009935625117311507202600000000000000000020000D015072026 PROPELG VI settlement 150726
B18: 009935625117321507202600000000000000000030000D015072026 PROPELG MC settlement 150726
B19: 009935646101191507202600000000000000000001000C015072026 PROPELG MC comm recd 150726
B20: 009935646101221507202600000000000000000001000C015072026 PROPELG VI comm recd 150726
B21: 009935646101191507202600000000000000000000200C015072026 PROPELG MC GST comm recd 150726
B22: 009935646101221507202600000000000000000000200C015072026 PROPELG VI GST comm recd 150726
B23: 009935646101191507202600000000000000000000100C015072026 PROPELG MC Non GST comm recd 150726
B24: 009935646101221507202600000000000000000000100C015072026 PROPELG VI Non GST comm recd 150726
B25: 200999103427 1507202600000000000000000047400C015072026 PROPELG-TXN Prp India 150726 150726

Sheet Setup
A1: SETUP AND TROUBLESHOOTING
A2: Read this if clicking a button on the Dashboard does nothing.
B4: Why a button can do nothing
B6: The buttons are drawings stored in the file, so they are always visible. What they run is a macro, and Excel will refuse to run macros in a file it does not trust. Work down this list - the first step fixes it most of the time.
B8: 1. Unblock the file (do this one first)
B9: Close the workbook. Find it in File Explorer, right-click it, choose Properties, tick Unblock at the bottom of the General tab, click OK, then open it again.
B11: Files that arrive by email or download carry a mark that makes Excel block their macros outright. Newer Excel shows a red bar for this - Enable Content will not appear, and clicking anything else will not help. Unblocking is the only fix.
B13: 2. Put the workbook in a trusted folder
B14: File > Options > Trust Center > Trust Center Settings > Trusted Locations > Add new location. Add the folder you keep this workbook in, then reopen it.
B16: 3. Check the macro setting itself
B17: File > Options > Trust Center > Trust Center Settings > Macro Settings. It should be Disable all macros with notification. If it is Disable all macros without notification, no prompt ever appears and nothing will run.
B19: 4. Check whether the macros arrived at all
B20: Press Alt+F8. If GenerateTTUM is in the list, the macros are present - run it straight from there, and the buttons will work once trust is sorted out. If the list is empty, the macros did not load, so do step 5.
B22: 5. Load the macros by hand (about a minute, needed only once)
... B33: Mixing files from different versions also breaks it - a workbook from one build with the macro from another. Take both from the same download.
